Workbook

Sheet Pre-MoneyBall(1993-2002)
A1: playerID | B1: yearID | C1: POSITION | D1: teamID | E1: lgID | F1: AB | G1: R | H1: H | I1: 2B | J1: 3B | K1: HR | L1: RBI | M1: BB | N1: SO | O1: IBB | P1: HBP | Q1: SH | R1: SF | S1: GIDP | T1: startingPos | U1: Batting Average | V1: On base percentage | W1: Slugging (Power) | X1: OPS (Offensive Value) | Y1: Walk % | Z1: Strikeout % | AA1: ISO (isolated power)
A2: alomaro01 | B2: 1993 | C2: =VLOOKUP(Pre[[#This Row],[startingPos]],AD3:AE12,2) -> #N/A | D2: TOR | E2: AL | F2: 589 | G2: 109 | H2: 192 | I2: 35 | J2: 6 | K2: 17 | L2: 93 | M2: 80 | N2: 67 | O2: 5.0 | P2: 5.0 | Q2: 4.0 | R2: 5.0 | S2: 13.0 | T2: 4.0 | U2: =H2/F2 -> 0.32597623 | V2: =(H2+M2+O2+P2)/(F2+M2+O2+P2+R2) -> 0.4122807 | W2: =((H2-I2-J2-K2)+(2*I2)+(3*J2)+(4*K2))/F2 -> 0.49235993 | X2: =V2+W2 -> 0.90464063 | Y2: =M2/(M2+F2) -> 0.11958146 | Z2: =N2/(N2+F2) -> 0.10213415 | AA2: =W2-U2 -> 0.1663837 | AD2: starting position references
A3: boggswa01 | B3: 1993 | C3: 1 | D3: NYA | E3: AL | F3: 560 | G3: 83 | H3: 169 | I3: 26 | J3: 1 | K3: 2 | L3: 59 | M3: 74 | N3: 49 | O3: 4.0 | P3: 0.0 | Q3: 1.0 | R3: 9.0 | S3: 10.0 | T3: 5.0 | U3: =H3/F3 -> 0.30178571 | V3: =(H3+M3+O3+P3)/(F3+M3+O3+P3+R3) -> 0.38176198 | W3: =((H3-I3-J3-K3)+(2*I3)+(3*J3)+(4*K3))/F3 -> 0.3625 | X3: =V3+W3 -> 0.74426198 | Y3: =M3/(M3+F3) -> 0.11671924 | Z3: =N3/(N3+F3) -> 0.08045977 | AA3: =W3-U3 -> 0.060714286 | AD3: 1 | AE3: P
A4: bondsba01 | B4: 1993 | C4: 1 | D4: SFN | E4: NL | F4: 539 | G4: 129 | H4: 181 | I4: 38 | J4: 4 | K4: 46 | L4: 123 | M4: 126 | N4: 79 | O4: 43.0 | P4: 2.0 | Q4: 0.0 | R4: 7.0 | S4: 11.0 | T4: 7.0 | U4: =H4/F4 -> 0.33580705 | V4: =(H4+M4+O4+P4)/(F4+M4+O4+P4+R4) -> 0.49093445 | W4: =((H4-I4-J4-K4)+(2*I4)+(3*J4)+(4*K4))/F4 -> 0.67717996 | X4: =V4+W4 -> 1.1681144 | Y4: =M4/(M4+F4) -> 0.18947368 | Z4: =N4/(N4+F4) -> 0.12783172 | AA4: =W4-U4 -> 0.34137291 | AD4: 2 | AE4: C
A5: cartejo01 | B5: 1993 | C5: 1 | D5: TOR | E5: AL | F5: 603 | G5: 92 | H5: 153 | I5: 33 | J5: 5 | K5: 33 | L5: 121 | M5: 47 | N5: 113 | O5: 5.0 | P5: 9.0 | Q5: 0.0 | R5: 10.0 | S5: 10.0 | T5: 9.0 | U5: =H5/F5 -> 0.25373134 | V5: =(H5+M5+O5+P5)/(F5+M5+O5+P5+R5) -> 0.31750742 | W5: =((H5-I5-J5-K5)+(2*I5)+(3*J5)+(4*K5))/F5 -> 0.48922056 | X5: =V5+W5 -> 0.80672798 | Y5: =M5/(M5+F5) -> 0.072307692 | Z5: =N5/(N5+F5) -> 0.15782123 | AA5: =W5-U5 -> 0.23548922 | AD5: 3 | AE5: 1B
A6: daultda01 | B6: 1993 | C6: 1 | D6: PHI | E6: NL | F6: 510 | G6: 90 | H6: 131 | I6: 35 | J6: 4 | K6: 24 | L6: 105 | M6: 117 | N6: 111 | O6: 12.0 | P6: 2.0 | Q6: 0.0 | R6: 8.0 | S6: 2.0 | T6: 2.0 | U6: =H6/F6 -> 0.25686275 | V6: =(H6+M6+O6+P6)/(F6+M6+O6+P6+R6) -> 0.403698 | W6: =((H6-I6-J6-K6)+(2*I6)+(3*J6)+(4*K6))/F6 -> 0.48235294 | X6: =V6+W6 -> 0.88605094 | Y6: =M6/(M6+F6) -> 0.18660287 | Z6: =N6/(N6+F6) -> 0.17874396 | AA6: =W6-U6 -> 0.2254902 | AD6: 4 | AE6: 2B
A7: gracema01 | B7: 1993 | C7: 1 | D7: CHN | E7: NL | F7: 594 | G7: 86 | H7: 193 | I7: 39 | J7: 4 | K7: 14 | L7: 98 | M7: 71 | N7: 32 | O7: 14.0 | P7: 1.0 | Q7: 1.0 | R7: 9.0 | S7: 25.0 | T7: 10.0 | U7: =H7/F7 -> 0.32491582 | V7: =(H7+M7+O7+P7)/(F7+M7+O7+P7+R7) -> 0.40493469 | W7: =((H7-I7-J7-K7)+(2*I7)+(3*J7)+(4*K7))/F7 -> 0.47474747 | X7: =V7+W7 -> 0.87968216 | Y7: =M7/(M7+F7) -> 0.10676692 | Z7: =N7/(N7+F7) -> 0.051118211 | AA7: =W7-U7 -> 0.14983165 | AD7: 5 | AE7: 3B
A8: griffke02 | B8: 1993 | C8: 1 | D8: SEA | E8: AL | F8: 582 | G8: 113 | H8: 180 | I8: 38 | J8: 3 | K8: 45 | L8: 109 | M8: 96 | N8: 91 | O8: 25.0 | P8: 6.0 | Q8: 0.0 | R8: 7.0 | S8: 14.0 | T8: 8.0 | U8: =H8/F8 -> 0.30927835 | V8: =(H8+M8+O8+P8)/(F8+M8+O8+P8+R8) -> 0.42877095 | W8: =((H8-I8-J8-K8)+(2*I8)+(3*J8)+(4*K8))/F8 -> 0.61683849 | X8: =V8+W8 -> 1.0456094 | Y8: =M8/(M8+F8) -> 0.14159292 | Z8: =N8/(N8+F8) -> 0.13521545 | AA8: =W8-U8 -> 0.30756014 | AD8: 6 | AE8: SS
A9: grissma02 | B9: 1993 | C9: 1 | D9: MON | E9: NL | F9: 630 | G9: 104 | H9: 188 | I9: 27 | J9: 2 | K9: 19 | L9: 95 | M9: 52 | N9: 76 | O9: 6.0 | P9: 3.0 | Q9: 0.0 | R9: 8.0 | S9: 9.0 | T9: 8.0 | U9: =H9/F9 -> 0.2984127 | V9: =(H9+M9+O9+P9)/(F9+M9+O9+P9+R9) -> 0.35622318 | W9: =((H9-I9-J9-K9)+(2*I9)+(3*J9)+(4*K9))/F9 -> 0.43809524 | X9: =V9+W9 -> 0.79431841 | Y9: =M9/(M9+F9) -> 0.076246334 | Z9: =N9/(N9+F9) -> 0.10764873 | AA9: =W9-U9 -> 0.13968254 | AD9: 7 | AE9: OF
A10: justida01 | B10: 1993 | C10: 1 | D10: ATL | E10: NL | F10: 585 | G10: 90 | H10: 158 | I10: 15 | J10: 4 | K10: 40 | L10: 120 | M10: 78 | N10: 90 | O10: 12.0 | P10: 3.0 | Q10: 0.0 | R10: 4.0 | S10: 9.0 | T10: 9.0 | U10: =H10/F10 -> 0.27008547 | V10: =(H10+M10+O10+P10)/(F10+M10+O10+P10+R10) -> 0.36803519 | W10: =((H10-I10-J10-K10)+(2*I10)+(3*J10)+(4*K10))/F10 -> 0.51452991 | X10: =V10+W10 -> 0.88256511 | Y10: =M10/(M10+F10) -> 0.11764706 | Z10: =N10/(N10+F10) -> 0.13333333 | AA10: =W10-U10 -> 0.24444444 | AD10: 8 | AE10: OF
A11: krukjo01 | B11: 1993 | C11: 1 | D11: PHI | E11: NL | F11: 535 | G11: 100 | H11: 169 | I11: 33 | J11: 5 | K11: 14 | L11: 85 | M11: 111 | N11: 87 | O11: 10.0 | P11: 0.0 | Q11: 0.0 | R11: 5.0 | S11: 11.0 | T11: 3.0 | U11: =H11/F11 -> 0.31588785 | V11: =(H11+M11+O11+P11)/(F11+M11+O11+P11+R11) -> 0.4387292 | W11: =((H11-I11-J11-K11)+(2*I11)+(3*J11)+(4*K11))/F11 -> 0.47476636 | X11: =V11+W11 -> 0.91349555 | Y11: =M11/(M11+F11) -> 0.17182663 | Z11: =N11/(N11+F11) -> 0.13987138 | AA11: =W11-U11 -> 0.1588785 | AD11: 9 | AE11: OF
A12: langsma01 | B12: 1993 | C12: 1 | D12: CAL | E12: AL | T12: 1.0 | U12: =H12/F12 -> #DIV/0! | V12: =(H12+M12+O12+P12)/(F12+M12+O12+P12+R12) -> #VALUE! | W12: =((H12-I12-J12-K12)+(2*I12)+(3*J12)+(4*K12))/F12 -> #DIV/0! | X12: =V12+W12 -> #VALUE! | Y12: =M12/(M12+F12) -> #DIV/0! | Z12: =N12/(N12+F12) -> #DIV/0! | AA12: =W12-U12 -> #DIV/0! | AD12: 10 | AE12: DH
A13: larkiba01 | B13: 1993 | C13: 1 | D13: CIN | E13: NL | F13: 384 | G13: 57 | H13: 121 | I13: 20 | J13: 3 | K13: 8 | L13: 51 | M13: 51 | N13: 33 | O13: 6.0 | P13: 1.0 | Q13: 1.0 | R13: 3.0 | S13: 13.0 | T13: 6.0 | U13: =H13/F13 -> 0.31510417 | V13: =(H13+M13+O13+P13)/(F13+M13+O13+P13+R13) -> 0.40224719 | W13: =((H13-I13-J13-K13)+(2*I13)+(3*J13)+(4*K13))/F13 -> 0.4453125 | X13: =V13+W13 -> 0.84755969 | Y13: =M13/(M13+F13) -> 0.11724138 | Z13: =N13/(N13+F13) -> 0.079136691 | AA13: =W13-U13 -> 0.13020833
A14: molitpa01 | B14: 1993 | C14: 1 | D14: TOR | E14: AL | F14: 636 | G14: 121 | H14: 211 | I14: 37 | J14: 5 | K14: 22 | L14: 111 | M14: 77 | N14: 71 | O14: 3.0 | P14: 3.0 | Q14: 1.0 | R14: 8.0 | S14: 13.0 | T14: 10.0 | U14: =H14/F14 -> 0.33176101 | V14: =(H14+M14+O14+P14)/(F14+M14+O14+P14+R14) -> 0.40440165 | W14: =((H14-I14-J14-K14)+(2*I14)+(3*J14)+(4*K14))/F14 -> 0.50943396 | X14: =V14+W14 -> 0.91383561 | Y14: =M14/(M14+F14) -> 0.10799439 | Z14: =N14/(N14+F14) -> 0.10042433 | AA14: =W14-U14 -> 0.17767296
A15: mulhote01 | B15: 1993 | C15: 1 | D15: PHI | E15: NL | F15: 62 | G15: 3 | H15: 4 | I15: 0 | J15: 0 | K15: 0 | L15: 0 | M15: 1 | N15: 27 | O15: 0.0 | P15: 0.0 | Q15: 8.0 | R15: 0.0 | S15: 0.0 | T15: 1.0 | U15: =H15/F15 -> 0.064516129 | V15: =(H15+M15+O15+P15)/(F15+M15+O15+P15+R15) -> 0.079365079 | W15: =((H15-I15-J15-K15)+(2*I15)+(3*J15)+(4*K15))/F15 -> 0.064516129 | X15: =V15+W15 -> 0.14388121 | Y15: =M15/(M15+F15) -> 0.015873016 | Z15: =N15/(N15+F15) -> 0.30337079 | AA15: =W15-U15 -> 0
A16: olerujo01 | B16: 1993 | C16: 1 | D16: TOR | E16: AL | F16: 551 | G16: 109 | H16: 200 | I16: 54 | J16: 2 | K16: 24 | L16: 107 | M16: 114 | N16: 65 | O16: 33.0 | P16: 7.0 | Q16: 0.0 | R16: 7.0 | S16: 12.0 | T16: 3.0 | U16: =H16/F16 -> 0.36297641 | V16: =(H16+M16+O16+P16)/(F16+M16+O16+P16+R16) -> 0.49719101 | W16: =((H16-I16-J16-K16)+(2*I16)+(3*J16)+(4*K16))/F16 -> 0.59891107 | X16: =V16+W16 -> 1.0961021 | Y16: =M16/(M16+F16) -> 0.17142857 | Z16: =N16/(N16+F16) -> 0.10551948 | AA16: =W16-U16 -> 0.23593466
A17: puckeki01 | B17: 1993 | C17: 1 | D17: MIN | E17: AL | F17: 622 | G17: 89 | H17: 184 | I17: 39 | J17: 3 | K17: 22 | L17: 89 | M17: 47 | N17: 93 | O17: 7.0 | P17: 7.0 | Q17: 1.0 | R17: 5.0 | S17: 15.0 | T17: 7.0 | U17: =H17/F17 -> 0.29581994 | V17: =(H17+M17+O17+P17)/(F17+M17+O17+P17+R17) -> 0.35610465 | W17: =((H17-I17-J17-K17)+(2*I17)+(3*J17)+(4*K17))/F17 -> 0.47427653 | X17: =V17+W17 -> 0.83038118 | Y17: =M17/(M17+F17) -> 0.070254111 | Z17: =N17/(N17+F17) -> 0.13006993 | AA17: =W17-U17 -> 0.17845659
A18: ripkeca01 | B18: 1993 | C18: 1 | D18: BAL | E18: AL | F18: 641 | G18: 87 | H18: 165 | I18: 26 | J18: 3 | K18: 24 | L18: 90 | M18: 65 | N18: 58 | O18: 19.0 | P18: 6.0 | Q18: 0.0 | R18: 6.0 | S18: 17.0 | T18: 6.0 | U18: =H18/F18 -> 0.2574103 | V18: =(H18+M18+O18+P18)/(F18+M18+O18+P18+R18) -> 0.34599729 | W18: =((H18-I18-J18-K18)+(2*I18)+(3*J18)+(4*K18))/F18 -> 0.41965679 | X18: =V18+W18 -> 0.76565407 | Y18: =M18/(M18+F18) -> 0.092067989 | Z18: =N18/(N18+F18) -> 0.08297568 | AA18: =W18-U18 -> 0.16224649
A19: rodriiv01 | B19: 1993 | C19: 1 | D19: TEX | E19: AL | F19: 473 | G19: 56 | H19: 129 | I19: 28 | J19: 4 | K19: 10 | L19: 66 | M19: 29 | N19: 70 | O19: 3.0 | P19: 4.0 | Q19: 5.0 | R19: 8.0 | S19: 16.0 | T19: 2.0 | U19: =H19/F19 -> 0.27272727 | V19: =(H19+M19+O19+P19)/(F19+M19+O19+P19+R19) -> 0.31914894 | W19: =((H19-I19-J19-K19)+(2*I19)+(3*J19)+(4*K19))/F19 -> 0.41226216 | X19: =V19+W19 -> 0.73141109 | Y19: =M19/(M19+F19) -> 0.057768924 | Z19: =N19/(N19+F19) -> 0.12891344 | AA19: =W19-U19 -> 0.13953488
A20: sandbry01 | B20: 1993 | C20: 1 | D20: CHN | E20: NL | F20: 456 | G20: 67 | H20: 141 | I20: 20 | J20: 0 | K20: 9 | L20: 45 | M20: 37 | N20: 62 | O20: 1.0 | P20: 2.0 | Q20: 2.0 | R20: 6.0 | S20: 12.0 | T20: 4.0 | U20: =H20/F20 -> 0.30921053 | V20: =(H20+M20+O20+P20)/(F20+M20+O20+P20+R20) -> 0.36055777 | W20: =((H20-I20-J20-K20)+(2*I20)+(3*J20)+(4*K20))/F20 -> 0.4122807 | X20: =V20+W20 -> 0.77283847 | Y20: =M20/(M20+F20) -> 0.07505071 | Z20: =N20/(N20+F20) -> 0.11969112 | AA20: =W20-U20 -> 0.10307018
A21: sheffga01 | B21: 1993 | C21: 1 | D21: SDN | E21: NL | F21: 258 | G21: 34 | H21: 76 | I21: 12 | J21: 2 | K21: 10 | L21: 36 | M21: 18 | N21: 30 | O21: 0.0 | P21: 3.0 | Q21: 0.0 | R21: 3.0 | S21: 9.0 | T21: 5.0 | U21: =H21/F21 -> 0.29457364 | V21: =(H21+M21+O21+P21)/(F21+M21+O21+P21+R21) -> 0.34397163 | W21: =((H21-I21-J21-K21)+(2*I21)+(3*J21)+(4*K21))/F21 -> 0.47286822 | X21: =V21+W21 -> 0.81683985 | Y21: =M21/(M21+F21) -> 0.065217391 | Z21: =N21/(N21+F21) -> 0.10416667 | AA21: =W21-U21 -> 0.17829457
A22: sheffga01 | B22: 1993 | C22: 2 | D22: FLO | E22: NL | F22: 236 | G22: 33 | H22: 69 | I22: 8 | J22: 3 | K22: 10 | L22: 37 | M22: 29 | N22: 34 | O22: 6.0 | P22: 6.0 | Q22: 0.0 | R22: 4.0 | S22: 2.0 | T22: 5.0 | U22: =H22/F22 -> 0.29237288 | V22: =(H22+M22+O22+P22)/(F22+M22+O22+P22+R22) -> 0.39145907 | W22: =((H22-I22-J22-K22)+(2*I22)+(3*J22)+(4*K22))/F22 -> 0.47881356 | X22: =V22+W22 -> 0.87027263 | Y22: =M22/(M22+F22) -> 0.10943396 | Z22: =N22/(N22+F22) -> 0.12592593 | AA22: =W22-U22 -> 0.18644068
A23: alomaro01 | B23: 1994 | C23: 1 | D23: TOR | E23: AL | F23: 392 | G23: 78 | H23: 120 | I23: 25 | J23: 4 | K23: 8 | L23: 38 | M23: 51 | N23: 41 | O23: 2.0 | P23: 2.0 | Q23: 7.0 | R23: 3.0 | S23: 14.0 | T23: 4.0 | U23: =H23/F23 -> 0.30612245 | V23: =(H23+M23+O23+P23)/(F23+M23+O23+P23+R23) -> 0.38888889 | W23: =((H23-I23-J23-K23)+(2*I23)+(3*J23)+(4*K23))/F23 -> 0.45153061 | X23: =V23+W23 -> 0.8404195 | Y23: =M23/(M23+F23) -> 0.11512415 | Z23: =N23/(N23+F23) -> 0.094688222 | AA23: =W23-U23 -> 0.14540816
A24: boggswa01 | B24: 1994 | C24: 1 | D24: NYA | E24: AL | F24: 366 | G24: 61 | H24: 125 | I24: 19 | J24: 1 | K24: 11 | L24: 55 | M24: 61 | N24: 29 | O24: 3.0 | P24: 1.0 | Q24: 2.0 | R24: 4.0 | S24: 10.0 | T24: 5.0 | U24: =H24/F24 -> 0.34153005 | V24: =(H24+M24+O24+P24)/(F24+M24+O24+P24+R24) -> 0.43678161 | W24: =((H24-I24-J24-K24)+(2*I24)+(3*J24)+(4*K24))/F24 -> 0.48907104 | X24: =V24+W24 -> 0.92585265 | Y24: =M24/(M24+F24) -> 0.14285714 | Z24: =N24/(N24+F24) -> 0.073417722 | AA24: =W24-U24 -> 0.14754098
... A31: justida01 | B31: 1994 | C31: 1 | D31: ATL | E31: NL | F31: 352 | G31: 61 | H31: 110 | I31: 16 | J31: 2 | K31: 19 | L31: 59 | M31: 69 | N31: 45 | O31: 5.0 | P31: 2.0 | Q31: 0.0 | R31: 1.0 | S31: 8.0 | T31: 9.0 | U31: =H31/F31 -> 0.3125 | V31: =(H31+M31+O31+P31)/(F31+M31+O31+P31+R31) -> 0.43356643 | W31: =((H31-I31-J31-K31)+(2*I31)+(3*J31)+(4*K31))/F31 -> 0.53125 | X31: =V31+W31 -> 0.96481643 | Y31: =M31/(M31+F31) -> 0.16389549 | Z31: =N31/(N31+F31) -> 0.11335013 | AA31: =W31-U31 -> 0.21875
A32: keyji01 | B32: 1994 | C32: 1 | D32: NYA | E32: AL | T32: 1.0 | U32: =H32/F32 -> #DIV/0! | V32: =(H32+M32+O32+P32)/(F32+M32+O32+P32+R32) -> #VALUE! | W32: =((H32-I32-J32-K32)+(2*I32)+(3*J32)+(4*K32))/F32 -> #DIV/0! | X32: =V32+W32 -> #VALUE! | Y32: =M32/(M32+F32) -> #DIV/0! | Z32: =N32/(N32+F32) -> #DIV/0! | AA32: =W32-U32 -> #DIV/0!
A33: maddugr01 | B33: 1994 | C33: 1 | D33: ATL | E33: NL | F33: 63 | G33: 5 | H33: 14 | I33: 2 | J33: 0 | K33: 0 | L33: 2 | M33: 1 | N33: 19 | O33: 0.0 | P33: 0.0 | Q33: 9.0 | R33: 0.0 | S33: 2.0 | T33: 1.0 | U33: =H33/F33 -> 0.22222222 | V33: =(H33+M33+O33+P33)/(F33+M33+O33+P33+R33) -> 0.234375 | W33: =((H33-I33-J33-K33)+(2*I33)+(3*J33)+(4*K33))/F33 -> 0.25396825 | X33: =V33+W33 -> 0.48834325 | Y33: =M33/(M33+F33) -> 0.015625 | Z33: =N33/(N33+F33) -> 0.23170732 | AA33: =W33-U33 -> 0.031746032
A34: piazzmi01 | B34: 1994 | C34: 1 | D34: LAN | E34: NL | F34: 405 | G34: 64 | H34: 129 | I34: 18 | J34: 0 | K34: 24 | L34: 92 | M34: 33 | N34: 65 | O34: 10.0 | P34: 1.0 | Q34: 0.0 | R34: 2.0 | S34: 11.0 | T34: 2.0 | U34: =H34/F34 -> 0.31851852 | V34: =(H34+M34+O34+P34)/(F34+M34+O34+P34+R34) -> 0.38359202 | W34: =((H34-I34-J34-K34)+(2*I34)+(3*J34)+(4*K34))/F34 -> 0.54074074 | X34: =V34+W34 -> 0.92433276 | Y34: =M34/(M34+F34) -> 0.075342466 | Z34: =N34/(N34+F34) -> 0.13829787 | AA34: =W34-U34 -> 0.22222222
A35: puckeki01 | B35: 1994 | C35: 1 | D35: MIN | E35: AL | F35: 439 | G35: 79 | H35: 139 | I35: 32 | J35: 3 | K35: 20 | L35: 112 | M35: 28 | N35: 47 | O35: 7.0 | P35: 7.0 | Q35: 1.0 | R35: 7.0 | S35: 11.0 | T35: 9.0 | U35: =H35/F35 -> 0.3166287 | V35: =(H35+M35+O35+P35)/(F35+M35+O35+P35+R35) -> 0.37090164 | W35: =((H35-I35-J35-K35)+(2*I35)+(3*J35)+(4*K35))/F35 -> 0.53986333 | X35: =V35+W35 -> 0.91076497 | Y35: =M35/(M35+F35) -> 0.059957173 | Z35: =N35/(N35+F35) -> 0.096707819 | AA35: =W35-U35 -> 0.22323462
A36: ripkeca01 | B36: 1994 | C36: 1 | D36: BAL | E36: AL | F36: 444 | G36: 71 | H36: 140 | I36: 19 | J36: 3 | K36: 13 | L36: 75 | M36: 32 | N36: 41 | O36: 3.0 | P36: 4.0 | Q36: 0.0 | R36: 4.0 | S36: 17.0 | T36: 6.0 | U36: =H36/F36 -> 0.31531532 | V36: =(H36+M36+O36+P36)/(F36+M36+O36+P36+R36) -> 0.36755647 | W36: =((H36-I36-J36-K36)+(2*I36)+(3*J36)+(4*K36))/F36 -> 0.45945946 | X36: =V36+W36 -> 0.82701593 | Y36: =M36/(M36+F36) -> 0.067226891 | Z36: =N36/(N36+F36) -> 0.084536082 | AA36: =W36-U36 -> 0.14414414
A37: rodriiv01 | B37: 1994 | C37: 1 | D37: TEX | E37: AL | F37: 363 | G37: 56 | H37: 108 | I37: 19 | J37: 1 | K37: 16 | L37: 57 | M37: 31 | N37: 42 | O37: 5.0 | P37: 7.0 | Q37: 0.0 | R37: 4.0 | S37: 10.0 | T37: 2.0 | U37: =H37/F37 -> 0.29752066 | V37: =(H37+M37+O37+P37)/(F37+M37+O37+P37+R37) -> 0.36829268 | W37: =((H37-I37-J37-K37)+(2*I37)+(3*J37)+(4*K37))/F37 -> 0.48760331 | X37: =V37+W37 -> 0.85589599 | Y37: =M37/(M37+F37) -> 0.078680203 | Z37: =N37/(N37+F37) -> 0.1037037 | AA37: =W37-U37 -> 0.19008264
A38: smithoz01 | B38: 1994 | C38: 1 | D38: SLN | E38: NL | F38: 381 | G38: 51 | H38: 100 | I38: 18 | J38: 3 | K38: 3 | L38: 30 | M38: 38 | N38: 26 | O38: 3.0 | P38: 0.0 | Q38: 10.0 | R38: 4.0 | S38: 3.0 | T38: 6.0 | U38: =H38/F38 -> 0.26246719 | V38: =(H38+M38+O38+P38)/(F38+M38+O38+P38+R38) -> 0.33098592 | W38: =((H38-I38-J38-K38)+(2*I38)+(3*J38)+(4*K38))/F38 -> 0.34908136 | X38: =V38+W38 -> 0.68006728 | Y38: =M38/(M38+F38) -> 0.090692124 | Z38: =N38/(N38+F38) -> 0.063882064 | AA38: =W38-U38 -> 0.086614173
A39: thomafr04 | B39: 1994 | C39: 1 | D39: CHA | E39: AL | F39: 399 | G39: 106 | H39: 141 | I39: 34 | J39: 1 | K39: 38 | L39: 101 | M39: 109 | N39: 61 | O39: 12.0 | P39: 2.0 | Q39: 0.0 | R39: 7.0 | S39: 15.0 | T39: 3.0 | U39: =H39/F39 -> 0.35338346 | V39: =(H39+M39+O39+P39)/(F39+M39+O39+P39+R39) -> 0.49905482 | W39: =((H39-I39-J39-K39)+(2*I39)+(3*J39)+(4*K39))/F39 -> 0.72932331 | X39: =V39+W39 -> 1.2283781 | Y39: =M39/(M39+F39) -> 0.21456693 | Z39: =N39/(N39+F39) -> 0.1326087 | AA39: =W39-U39 -> 0.37593985
A40: willima04 | B40: 1994 | C40: 1 | D40: SFN | E40: NL | F40: 445 | G40: 74 | H40: 119 | I40: 16 | J40: 3 | K40: 43 | L40: 96 | M40: 33 | N40: 87 | O40: 7.0 | P40: 2.0 | Q40: 0.0 | R40: 3.0 | S40: 11.0 | T40: 5.0 | U40: =H40/F40 -> 0.26741573 | V40: =(H40+M40+O40+P40)/(F40+M40+O40+P40+R40) -> 0.32857143 | W40: =((H40-I40-J40-K40)+(2*I40)+(3*J40)+(4*K40))/F40 -> 0.60674157 | X40: =V40+W40 -> 0.935313 | Y40: =M40/(M40+F40) -> 0.069037657 | Z40: =N40/(N40+F40) -> 0.16353383 | AA40: =W40-U40 -> 0.33932584
A41: baergca01 | B41: 1995 | C41: 1 | D41: CLE | E41: AL | F41: 557 | G41: 87 | H41: 175 | I41: 28 | J41: 2 | K41: 15 | L41: 90 | M41: 35 | N41: 31 | O41: 6.0 | P41: 3.0 | Q41: 0.0 | R41: 5.0 | S41: 15.0 | T41: 4.0 | U41: =H41/F41 -> 0.31418312 | V41: =(H41+M41+O41+P41)/(F41+M41+O41+P41+R41) -> 0.36138614 | W41: =((H41-I41-J41-K41)+(2*I41)+(3*J41)+(4*K41))/F41 -> 0.4524237 | X41: =V41+W41 -> 0.81380984 | Y41: =M41/(M41+F41) -> 0.059121622 | Z41: =N41/(N41+F41) -> 0.052721088 | AA41: =W41-U41 -> 0.13824057
A42: belleal01 | B42: 1995 | C42: 1 | D42: CLE | E42: AL | F42: 546 | G42: 121 | H42: 173 | I42: 52 | J42: 1 | K42: 50 | L42: 126 | M42: 73 | N42: 80 | O42: 5.0 | P42: 6.0 | Q42: 0.0 | R42: 4.0 | S42: 24.0 | T42: 7.0 | U42: =H42/F42 -> 0.31684982 | V42: =(H42+M42+O42+P42)/(F42+M42+O42+P42+R42) -> 0.40536278 | W42: =((H42-I42-J42-K42)+(2*I42)+(3*J42)+(4*K42))/F42 -> 0.69047619 | X42: =V42+W42 -> 1.095839 | Y42: =M42/(M42+F42) -> 0.11793215 | Z42: =N42/(N42+F42) -> 0.12779553 | AA42: =W42-U42 -> 0.37362637
A43: biggicr01 | B43: 1995 | C43: 1 | D43: HOU | E43: NL | F43: 553 | G43: 123 | H43: 167 | I43: 30 | J43: 2 | K43: 22 | L43: 77 | M43: 80 | N43: 85 | O43: 1.0 | P43: 22.0 | Q43: 11.0 | R43: 7.0 | S43: 6.0 | T43: 4.0 | U43: =H43/F43 -> 0.30198915 | V43: =(H43+M43+O43+P43)/(F43+M43+O43+P43+R43) -> 0.40723982 | W43: =((H43-I43-J43-K43)+(2*I43)+(3*J43)+(4*K43))/F43 -> 0.48282098 | X43: =V43+W43 -> 0.8900608 | Y43: =M43/(M43+F43) -> 0.12638231 | Z43: =N43/(N43+F43) -> 0.13322884 | AA43: =W43-U43 -> 0.18083183
A44: boggswa01 | B44: 1995 | C44: 1 | D44: NYA | E44: AL | F44: 460 | G44: 76 | H44: 149 | I44: 22 | J44: 4 | K44: 5 | L44: 63 | M44: 74 | N44: 50 | O44: 5.0 | P44: 0.0 | Q44: 0.0 | R44: 7.0 | S44: 13.0 | T44: 5.0 | U44: =H44/F44 -> 0.32391304 | V44: =(H44+M44+O44+P44)/(F44+M44+O44+P44+R44) -> 0.41758242 | W44: =((H44-I44-J44-K44)+(2*I44)+(3*J44)+(4*K44))/F44 -> 0.42173913 | X44: =V44+W44 -> 0.83932155 | Y44: =M44/(M44+F44) -> 0.13857678 | Z44: =N44/(N44+F44) -> 0.098039216 | AA44: =W44-U44 -> 0.097826087
... A49: gwynnto01 | B49: 1995 | C49: 1 | D49: SDN | E49: NL | F49: 535 | G49: 82 | H49: 197 | I49: 33 | J49: 1 | K49: 9 | L49: 90 | M49: 35 | N49: 15 | O49: 10.0 | P49: 1.0 | Q49: 0.0 | R49: 6.0 | S49: 20.0 | T49: 9.0 | U49: =H49/F49 -> 0.3682243 | V49: =(H49+M49+O49+P49)/(F49+M49+O49+P49+R49) -> 0.41396934 | W49: =((H49-I49-J49-K49)+(2*I49)+(3*J49)+(4*K49))/F49 -> 0.48411215 | X49: =V49+W49 -> 0.89808149 | Y49: =M49/(M49+F49) -> 0.061403509 | Z49: =N49/(N49+F49) -> 0.027272727 | AA49: =W49-U49 -> 0.11588785
A50: johnsra05 | B50: 1995 | C50: 1 | D50: SEA | E50: AL | T50: 1.0 | U50: =H50/F50 -> #DIV/0! | V50: =(H50+M50+O50+P50)/(F50+M50+O50+P50+R50) -> #VALUE! | W50: =((H50-I50-J50-K50)+(2*I50)+(3*J50)+(4*K50))/F50 -> #DIV/0! | X50: =V50+W50 -> #VALUE! | Y50: =M50/(M50+F50) -> #DIV/0! | Z50: =N50/(N50+F50) -> #DIV/0! | AA50: =W50-U50 -> #DIV/0!
...

Sheet MoneyBall(2003-2013)
A1: playerID | B1: yearID | C1: stint | D1: teamID | E1: lgID | F1: G | G1: AB | H1: R | I1: H | J1: 2B | K1: 3B | L1: HR | M1: RBI | N1: SB | O1: CS | P1: BB | Q1: SO | R1: IBB | S1: HBP | T1: SH | U1: SF | V1: GIDP | W1: startingPos | X1: Batting Average | Y1: On base percentage | Z1: Slugging (Power) | AA1: OPS (Offensive Value) | AB1: Walk % | AC1: Strikeout % | AD1: ISO (isolated power)
A2: anderga01 | B2: 2003 | C2: 1 | D2: ANA | E2: AL | F2: 159 | G2: 638 | H2: 80 | I2: 201 | J2: 49 | K2: 4 | L2: 29 | M2: 116 | N2: 6 | O2: 3 | P2: 31 | Q2: 83 | R2: 10.0 | S2: 0.0 | T2: 0.0 | U2: 4.0 | V2: 15.0 | W2: 7.0 | X2: =I2/G2 -> 0.31504702 | Y2: =(I2+P2+R2+S2)/(G2+P2+R2+S2+U2) -> 0.35431918 | Z2: =((I2-J2-K2-L2)+(2*J2)+(3*K2)+(4*L2))/G2 -> 0.54075235 | AA2: =Y2+Z2 -> 0.89507153 | AB2: =P2/(P2+G2) -> 0.046337818 | AC2: =Q2/(Q2+G2) -> 0.11511789 | AD2: =Z2-X2 -> 0.22570533
A3: bondsba01 | B3: 2003 | C3: 1 | D3: SFN | E3: NL | F3: 130 | G3: 390 | H3: 111 | I3: 133 | J3: 22 | K3: 1 | L3: 45 | M3: 90 | N3: 7 | O3: 0 | P3: 148 | Q3: 58 | R3: 61.0 | S3: 10.0 | T3: 0.0 | U3: 2.0 | V3: 7.0 | W3: 10.0 | X3: =I3/G3 -> 0.34102564 | Y3: =(I3+P3+R3+S3)/(G3+P3+R3+S3+U3) -> 0.57610475 | Z3: =((I3-J3-K3-L3)+(2*J3)+(3*K3)+(4*L3))/G3 -> 0.74871795 | AA3: =Y3+Z3 -> 1.3248227 | AB3: =P3/(P3+G3) -> 0.27509294 | AC3: =Q3/(Q3+G3) -> 0.12946429 | AD3: =Z3-X3 -> 0.40769231
A4: delgaca01 | B4: 2003 | C4: 1 | D4: TOR | E4: AL | F4: 161 | G4: 570 | H4: 117 | I4: 172 | J4: 38 | K4: 1 | L4: 42 | M4: 145 | N4: 0 | O4: 0 | P4: 109 | Q4: 137 | R4: 23.0 | S4: 19.0 | T4: 0.0 | U4: 7.0 | V4: 9.0 | W4: 3.0 | X4: =I4/G4 -> 0.30175439 | Y4: =(I4+P4+R4+S4)/(G4+P4+R4+S4+U4) -> 0.44368132 | Z4: =((I4-J4-K4-L4)+(2*J4)+(3*K4)+(4*L4))/G4 -> 0.59298246 | AA4: =Y4+Z4 -> 1.0366638 | AB4: =P4/(P4+G4) -> 0.16053019 | AC4: =Q4/(Q4+G4) -> 0.19377652 | AD4: =Z4-X4 -> 0.29122807
A5: edmonji01 | B5: 2003 | C5: 1 | D5: SLN | E5: NL | F5: 137 | G5: 447 | H5: 89 | I5: 123 | J5: 32 | K5: 2 | L5: 39 | M5: 89 | N5: 1 | O5: 3 | P5: 77 | Q5: 127 | R5: 6.0 | S5: 4.0 | T5: 1.0 | U5: 2.0 | V5: 11.0 | W5: 8.0 | X5: =I5/G5 -> 0.27516779 | Y5: =(I5+P5+R5+S5)/(G5+P5+R5+S5+U5) -> 0.39179104 | Z5: =((I5-J5-K5-L5)+(2*J5)+(3*K5)+(4*L5))/G5 -> 0.61744966 | AA5: =Y5+Z5 -> 1.0092407 | AB5: =P5/(P5+G5) -> 0.14694656 | AC5: =Q5/(Q5+G5) -> 0.22125436 | AD5: =Z5-X5 -> 0.34228188
A6: glaustr01 | B6: 2003 | C6: 1 | D6: ANA | E6: AL | F6: 91 | G6: 319 | H6: 53 | I6: 79 | J6: 17 | K6: 2 | L6: 16 | M6: 50 | N6: 7 | O6: 2 | P6: 46 | Q6: 73 | R6: 4.0 | S6: 1.0 | T6: 0.0 | U6: 1.0 | V6: 8.0 | W6: 5.0 | X6: =I6/G6 -> 0.2476489 | Y6: =(I6+P6+R6+S6)/(G6+P6+R6+S6+U6) -> 0.35040431 | Z6: =((I6-J6-K6-L6)+(2*J6)+(3*K6)+(4*L6))/G6 -> 0.46394984 | AA6: =Y6+Z6 -> 0.81435416 | AB6: =P6/(P6+G6) -> 0.1260274 | AC6: =Q6/(Q6+G6) -> 0.18622449 | AD6: =Z6-X6 -> 0.21630094
A7: heltoto01 | B7: 2003 | C7: 1 | D7: COL | E7: NL | F7: 160 | G7: 583 | H7: 135 | I7: 209 | J7: 49 | K7: 5 | L7: 33 | M7: 117 | N7: 0 | O7: 4 | P7: 111 | Q7: 72 | R7: 21.0 | S7: 2.0 | T7: 0.0 | U7: 7.0 | V7: 19.0 | W7: 3.0 | X7: =I7/G7 -> 0.35849057 | Y7: =(I7+P7+R7+S7)/(G7+P7+R7+S7+U7) -> 0.47375691 | Z7: =((I7-J7-K7-L7)+(2*J7)+(3*K7)+(4*L7))/G7 -> 0.62950257 | AA7: =Y7+Z7 -> 1.1032595 | AB7: =P7/(P7+G7) -> 0.15994236 | AC7: =Q7/(Q7+G7) -> 0.10992366 | AD7: =Z7-X7 -> 0.27101201
A8: loaizes01 | B8: 2003 | C8: 1 | D8: CHA | E8: AL | F8: 34 | G8: 5 | H8: 1 | I8: 1 | J8: 0 | K8: 0 | L8: 0 | M8: 0 | N8: 0 | O8: 0 | P8: 0 | Q8: 2 | R8: 0.0 | S8: 0.0 | T8: 1.0 | U8: 0.0 | V8: 0.0 | W8: 1.0 | X8: =I8/G8 -> 0.2 | Y8: =(I8+P8+R8+S8)/(G8+P8+R8+S8+U8) -> 0.2 | Z8: =((I8-J8-K8-L8)+(2*J8)+(3*K8)+(4*L8))/G8 -> 0.2 | AA8: =Y8+Z8 -> 0.4 | AB8: =P8/(P8+G8) -> 0 | AC8: =Q8/(Q8+G8) -> 0.28571429 | AD8: =Z8-X8 -> 0
A9: lopezja01 | B9: 2003 | C9: 1 | D9: ATL | E9: NL | F9: 129 | G9: 457 | H9: 89 | I9: 150 | J9: 29 | K9: 3 | L9: 43 | M9: 109 | N9: 0 | O9: 1 | P9: 33 | Q9: 90 | R9: 5.0 | S9: 4.0 | T9: 0.0 | U9: 1.0 | V9: 10.0 | W9: 2.0 | X9: =I9/G9 -> 0.32822757 | Y9: =(I9+P9+R9+S9)/(G9+P9+R9+S9+U9) -> 0.384 | Z9: =((I9-J9-K9-L9)+(2*J9)+(3*K9)+(4*L9))/G9 -> 0.68708972 | AA9: =Y9+Z9 -> 1.0710897 | AB9: =P9/(P9+G9) -> 0.067346939 | AC9: =Q9/(Q9+G9) -> 0.16453382 | AD9: =Z9-X9 -> 0.35886214
A10: martied01 | B10: 2003 | C10: 1 | D10: SEA | E10: AL | F10: 145 | G10: 497 | H10: 72 | I10: 146 | J10: 25 | K10: 0 | L10: 24 | M10: 98 | N10: 0 | O10: 1 | P10: 92 | Q10: 95 | R10: 7.0 | S10: 7.0 | T10: 0.0 | U10: 7.0 | V10: 17.0 | W10: 10.0 | X10: =I10/G10 -> 0.29376258 | Y10: =(I10+P10+R10+S10)/(G10+P10+R10+S10+U10) -> 0.41311475 | Z10: =((I10-J10-K10-L10)+(2*J10)+(3*K10)+(4*L10))/G10 -> 0.4889336 | AA10: =Y10+Z10 -> 0.90204836 | AB10: =P10/(P10+G10) -> 0.15619694 | AC10: =Q10/(Q10+G10) -> 0.16047297 | AD10: =Z10-X10 -> 0.19517103
A11: matsuhi01 | B11: 2003 | C11: 1 | D11: NYA | E11: AL | F11: 163 | G11: 623 | H11: 82 | I11: 179 | J11: 42 | K11: 1 | L11: 16 | M11: 106 | N11: 2 | O11: 2 | P11: 63 | Q11: 86 | R11: 5.0 | S11: 3.0 | T11: 0.0 | U11: 6.0 | V11: 25.0 | W11: 8.0 | X11: =I11/G11 -> 0.28731942 | Y11: =(I11+P11+R11+S11)/(G11+P11+R11+S11+U11) -> 0.35714286 | Z11: =((I11-J11-K11-L11)+(2*J11)+(3*K11)+(4*L11))/G11 -> 0.43499197 | AA11: =Y11+Z11 -> 0.79213483 | AB11: =P11/(P11+G11) -> 0.091836735 | AC11: =Q11/(Q11+G11) -> 0.1212976 | AD11: =Z11-X11 -> 0.14767255
A12: posadjo01 | B12: 2003 | C12: 1 | D12: NYA | E12: AL | F12: 142 | G12: 481 | H12: 83 | I12: 135 | J12: 24 | K12: 0 | L12: 30 | M12: 101 | N12: 2 | O12: 4 | P12: 93 | Q12: 110 | R12: 6.0 | S12: 10.0 | T12: 0.0 | U12: 4.0 | V12: 13.0 | W12: 2.0 | X12: =I12/G12 -> 0.28066528 | Y12: =(I12+P12+R12+S12)/(G12+P12+R12+S12+U12) -> 0.41077441 | Z12: =((I12-J12-K12-L12)+(2*J12)+(3*K12)+(4*L12))/G12 -> 0.51767152 | AA12: =Y12+Z12 -> 0.92844593 | AB12: =P12/(P12+G12) -> 0.16202091 | AC12: =Q12/(Q12+G12) -> 0.18612521 | AD12: =Z12-X12 -> 0.23700624
A13: pujolal01 | B13: 2003 | C13: 1 | D13: SLN | E13: NL | F13: 157 | G13: 591 | H13: 137 | I13: 212 | J13: 51 | K13: 1 | L13: 43 | M13: 124 | N13: 5 | O13: 1 | P13: 79 | Q13: 65 | R13: 12.0 | S13: 10.0 | T13: 0.0 | U13: 5.0 | V13: 13.0 | W13: 7.0 | X13: =I13/G13 -> 0.35871404 | Y13: =(I13+P13+R13+S13)/(G13+P13+R13+S13+U13) -> 0.44906743 | Z13: =((I13-J13-K13-L13)+(2*J13)+(3*K13)+(4*L13))/G13 -> 0.66666667 | AA13: =Y13+Z13 -> 1.1157341 | AB13: =P13/(P13+G13) -> 0.11791045 | AC13: =Q13/(Q13+G13) -> 0.099085366 | AD13: =Z13-X13 -> 0.30795262
... A215: wrighda03 | B215: 2013 | C215: 1 | D215: NYN | E215: NL | F215: 112 | G215: 430 | H215: 63 | I215: 132 | J215: 23 | K215: 6 | L215: 18 | M215: 58 | N215: 17 | O215: 3 | P215: 55 | Q215: 79 | R215: 5.0 | S215: 5.0 | T215: 0.0 | U215: 2.0 | V215: 11.0 | W215: 5.0 | X215: =I215/G215 -> 0.30697674 | Y215: =(I215+P215+R215+S215)/(G215+P215+R215+S215+U215) -> 0.39637827 | Z215: =((I215-J215-K215-L215)+(2*J215)+(3*K215)+(4*L215))/G215 -> 0.51395349 | AA215: =Y215+Z215 -> 0.91033176 | AB215: =P215/(P215+G215) -> 0.11340206 | AC215: =Q215/(Q215+G215) -> 0.15520629 | AD215: =Z215-X215 -> 0.20697674

Sheet Cleaned MLB Stats Dataset
A1: Era | B1: Year | C1: Player | D1: League | E1: Team | F1: Position | G1: Position# | H1: At Bats | I1: Hits | J1: 2B | K1: 3B | L1: HR | M1: Runs | N1: RBI | O1: Strikeouts | P1: Walks | Q1: Int Walks | R1: Hit By Pitch | S1: Sac Fly | T1: Sac Bunt | U1: Batting Average | V1: Strikeout % | W1: Walk % | X1: On Base Percentage | Y1: Slugging % | Z1: OPS (On Base + Slugging) | AA1: ISO (Isolated Power | AB1: EA Batting Avg. | AC1: EA On Base % | AD1: EA Slugging % | AE1: EA On Base + Slugging | AF1: EA ISO
A2: Moneyball Era | B2: 2012 | C2: napolmi01 | D2: AL | E2: TEX | F2: =_xlfn.XLOOKUP(Cleaned_MLB_Stats_Dataset__1[[#This Row],[Position'#]],$B$373:$B$382,$A$373:$A$382) -> C | G2: 2 | H2: 352 | I2: 80 | J2: 9 | K2: 2 | L2: 24 | M2: 53 | N2: 56 | O2: 125 | P2: 56 | Q2: 5 | R2: 7 | S2: 2 | T2: 0 | U2: =Cleaned_MLB_Stats_Dataset__1[[#This Row],[Hits]]/Cleaned_MLB_Stats_Dataset__1[[#This Row],[At Bats]] -> 0.22727273 | V2: =Cleaned_MLB_Stats_Dataset__1[[#This Row],[Strikeouts]]/(Cleaned_MLB_Stats_Dataset__1[[#This Row],[At Bats]]+Cleaned_MLB_Stats_Dataset__1[[#This Row],[Walks]]) -> 0.30637255 | W2: =(Cleaned_MLB_Stats_Dataset__1[[#This Row],[Walks]]+Cleaned_MLB_Stats_Dataset__1[[#This Row],[Hit By Pitch]])/(Cleaned_MLB_Stats_Dataset__1[[#This Row],[At Bats]]+Cleaned_MLB_Stats_Dataset__1[[#This Row],[Walks]]+Cleaned_MLB_Stats_Dataset__1[[#This Row],[Hit By Pitch]]) -> 0.15180723 | X2: =(Cleaned_MLB_Stats_Dataset__1[[#This Row],[Hits]]+Cleaned_MLB_Stats_Dataset__1[[#This Row],[Walks]]+Cleaned_MLB_Stats_Dataset__1[[#This Row],[Hit By Pitch]])/(Cleaned_MLB_Stats_Dataset__1[[#This Row],[At Bats]]+Cleaned_MLB_Stats_Dataset__1[[#This Row],[Walks]]+Cleaned_MLB_Stats_Dataset__1[[#This Row],[Hit By Pitch]]+Cleaned_MLB_Stats_Dataset__1[[#This Row],[Sac Fly]]) -> 0.34292566 | Y2: =((Cleaned_MLB_Stats_Dataset__1[[#This Row],[Hits]]-(Cleaned_MLB_Stats_Dataset__1[[#This Row],[2B]]+Cleaned_MLB_Stats_Dataset__1[[#This Row],[3B]]+Cleaned_MLB_Stats_Dataset__1[[#This Row],[HR]]))+(Cleaned_MLB_Stats_Dataset__1[[#This Row],[2B]]*2)+(Cleaned_MLB_Stats_Dataset__1[[#This Row],[3B]]*3)+(Cleaned_MLB_Stats_Dataset__1[[#This Row],[HR]]*4))/Cleaned_MLB_Stats_Dataset__1[[#This Row],[At Bats]] -> 0.46875 | Z2: =Cleaned_MLB_Stats_Dataset__1[[#This Row],[On Base Percentage]]+Cleaned_MLB_Stats_Dataset__1[[#This Row],[Slugging %]] -> 0.81167566 | AA2: =Cleaned_MLB_Stats_Dataset__1[[#This Row],[Slugging %]]-Cleaned_MLB_Stats_Dataset__1[[#This Row],[Batting Average]] -> 0.24147727 | AB2: =Cleaned_MLB_Stats_Dataset__1[[#This Row],[Batting Average]]-_xlfn.XLOOKUP(Cleaned_MLB_Stats_Dataset__1[[#This Row],[Year]],'League Averages'!$A$3:$A$23,'League Averages'!$B$3:$B$23) -> -0.027727273 | AC2: =Cleaned_MLB_Stats_Dataset__1[[#This Row],[On Base Percentage]]-_xlfn.XLOOKUP(Cleaned_MLB_Stats_Dataset__1[[#This Row],[Year]],'League Averages'!$A$3:$A$23,'League Averages'!$C$3:$C$23) -> 0.023925659 | AD2: =Cleaned_MLB_Stats_Dataset__1[[#This Row],[Slugging %]]-_xlfn.XLOOKUP(Cleaned_MLB_Stats_Dataset__1[[#This Row],[Year]],'League Averages'!$A$3:$A$23,'League Averages'!$D$3:$D$23) -> 0.06375 | AE2: =Cleaned_MLB_Stats_Dataset__1[[#This Row],[OPS (On Base + Slugging)]]-_xlfn.XLOOKUP(Cleaned_MLB_Stats_Dataset__1[[#This Row],[Year]],'League Averages'!$A$3:$A$23,'League Averages'!$E$3:$E$23) -> 0.087675659 | AF2: =Cleaned_MLB_Stats_Dataset__1[[#This Row],[ISO (Isolated Power]]-_xlfn.XLOOKUP(Cleaned_MLB_Stats_Dataset__1[[#This Row],[Year]],'League Averages'!$A$3:$A$23,'League Averages'!$F$3:$F$23) -> 0.091477273
A3: Moneyball Era | B3: 2013 | C3: davisch02 | D3: AL | E3: BAL | F3: =_xlfn.XLOOKUP(Cleaned_MLB_Stats_Dataset__1[[#This Row],[Position'#]],$B$373:$B$382,$A$373:$A$382) -> 1B | G3: 3 | H3: 584 | I3: 167 | J3: 42 | K3: 1 | L3: 53 | M3: 103 | N3: 138 | O3: 199 | P3: 72 | Q3: 12 | R3: 10 | S3: 7 | T3: 0 | U3: =Cleaned_MLB_Stats_Dataset__1[[#This Row],[Hits]]/Cleaned_MLB_Stats_Dataset__1[[#This Row],[At Bats]] -> 0.2859589 | V3: =Cleaned_MLB_Stats_Dataset__1[[#This Row],[Strikeouts]]/(Cleaned_MLB_Stats_Dataset__1[[#This Row],[At Bats]]+Cleaned_MLB_Stats_Dataset__1[[#This Row],[Walks]]) -> 0.30335366 | W3: =(Cleaned_MLB_Stats_Dataset__1[[#This Row],[Walks]]+Cleaned_MLB_Stats_Dataset__1[[#This Row],[Hit By Pitch]])/(Cleaned_MLB_Stats_Dataset__1[[#This Row],[At Bats]]+Cleaned_MLB_Stats_Dataset__1[[#This Row],[Walks]]+Cleaned_MLB_Stats_Dataset__1[[#This Row],[Hit By Pitch]]) -> 0.12312312 | X3: =(Cleaned_MLB_Stats_Dataset__1[[#This Row],[Hits]]+Cleaned_MLB_Stats_Dataset__1[[#This Row],[Walks]]+Cleaned_MLB_Stats_Dataset__1[[#This Row],[Hit By Pitch]])/(Cleaned_MLB_Stats_Dataset__1[[#This Row],[At Bats]]+Cleaned_MLB_Stats_Dataset__1[[#This Row],[Walks]]+Cleaned_MLB_Stats_Dataset__1[[#This Row],[Hit By Pitch]]+Cleaned_MLB_Stats_Dataset__1[[#This Row],[Sac Fly]]) -> 0.36998514 | Y3: =((Cleaned_MLB_Stats_Dataset__1[[#This Row],[Hits]]-(Cleaned_MLB_Stats_Dataset__1[[#This Row],[2B]]+Cleaned_MLB_Stats_Dataset__1[[#This Row],[3B]]+Cleaned_MLB_Stats_Dataset__1[[#This Row],[HR]]))+(Cleaned_MLB_Stats_Dataset__1[[#This Row],[2B]]*2)+(Cleaned_MLB_Stats_Dataset__1[[#This Row],[3B]]*3)+(Cleaned_MLB_Stats_Dataset__1[[#This Row],[HR]]*4))/Cleaned_MLB_Stats_Dataset__1[[#This Row],[At Bats]] -> 0.63356164 | Z3: =Cleaned_MLB_Stats_Dataset__1[[#This Row],[On Base Percentage]]+Cleaned_MLB_Stats_Dataset__1[[#This Row],[Slugging %]] -> 1.0035468 | AA3: =Cleaned_MLB_Stats_Dataset__1[[#This Row],[Slugging %]]-Cleaned_MLB_Stats_Dataset__1[[#This Row],[Batting Average]] -> 0.34760274 | AB3: =Cleaned_MLB_Stats_Dataset__1[[#This Row],[Batting Average]]-_xlfn.XLOOKUP(Cleaned_MLB_Stats_Dataset__1[[#This Row],[Year]],'League Averages'!$A$3:$A$23,'League Averages'!$B$3:$B$23) -> 0.032958904 | AC3: =Cleaned_MLB_Stats_Dataset__1[[#This Row],[On Base Percentage]]-_xlfn.XLOOKUP(Cleaned_MLB_Stats_Dataset__1[[#This Row],[Year]],'League Averages'!$A$3:$A$23,'League Averages'!$C$3:$C$23) -> 0.051985141 | AD3: =Cleaned_MLB_Stats_Dataset__1[[#This Row],[Slugging %]]-_xlfn.XLOOKUP(Cleaned_MLB_Stats_Dataset__1[[#This Row],[Year]],'League Averages'!$A$3:$A$23,'League Averages'!$D$3:$D$23) -> 0.23756164 | AE3: =Cleaned_MLB_Stats_Dataset__1[[#This Row],[OPS (On Base + Slugging)]]-_xlfn.XLOOKUP(Cleaned_MLB_Stats_Dataset__1[[#This Row],[Year]],'League Averages'!$A$3:$A$23,'League Averages'!$E$3:$E$23) -> 0.28954678 | AF3: =Cleaned_MLB_Stats_Dataset__1[[#This Row],[ISO (Isolated Power]]-_xlfn.XLOOKUP(Cleaned_MLB_Stats_Dataset__1[[#This Row],[Year]],'League Averages'!$A$3:$A$23,'League Averages'!$F$3:$F$23) -> 0.20460274
A4: Moneyball Era | B4: 2012 | C4: grandcu01 | D4: AL | E4: NYA | F4: =_xlfn.XLOOKUP(Cleaned_MLB_Stats_Dataset__1[[#This Row],[Position'#]],$B$373:$B$382,$A$373:$A$382) -> CF | G4: 8 | H4: 596 | I4: 138 | J4: 18 | K4: 4 | L4: 43 | M4: 102 | N4: 106 | O4: 195 | P4: 75 | Q4: 4 | R4: 5 | S4: 7 | T4: 1 | U4: =Cleaned_MLB_Stats_Dataset__1[[#This Row],[Hits]]/Cleaned_MLB_Stats_Dataset__1[[#This Row],[At Bats]] -> 0.23154362 | V4: =Cleaned_MLB_Stats_Dataset__1[[#This Row],[Strikeouts]]/(Cleaned_MLB_Stats_Dataset__1[[#This Row],[At Bats]]+Cleaned_MLB_Stats_Dataset__1[[#This Row],[Walks]]) -> 0.29061103 | W4: =(Cleaned_MLB_Stats_Dataset__1[[#This Row],[Walks]]+Cleaned_MLB_Stats_Dataset__1[[#This Row],[Hit By Pitch]])/(Cleaned_MLB_Stats_Dataset__1[[#This Row],[At Bats]]+Cleaned_MLB_Stats_Dataset__1[[#This Row],[Walks]]+Cleaned_MLB_Stats_Dataset__1[[#This Row],[Hit By Pitch]]) -> 0.1183432 | X4: =(Cleaned_MLB_Stats_Dataset__1[[#This Row],[Hits]]+Cleaned_MLB_Stats_Dataset__1[[#This Row],[Walks]]+Cleaned_MLB_Stats_Dataset__1[[#This Row],[Hit By Pitch]])/(Cleaned_MLB_Stats_Dataset__1[[#This Row],[At Bats]]+Cleaned_MLB_Stats_Dataset__1[[#This Row],[Walks]]+Cleaned_MLB_Stats_Dataset__1[[#This Row],[Hit By Pitch]]+Cleaned_MLB_Stats_Dataset__1[[#This Row],[Sac Fly]]) -> 0.31918009 | Y4: =((Cleaned_MLB_Stats_Dataset__1[[#This Row],[Hits]]-(Cleaned_MLB_Stats_Dataset__1[[#This Row],[2B]]+Cleaned_MLB_Stats_Dataset__1[[#This Row],[3B]]+Cleaned_MLB_Stats_Dataset__1[[#This Row],[HR]]))+(Cleaned_MLB_Stats_Dataset__1[[#This Row],[2B]]*2)+(Cleaned_MLB_Stats_Dataset__1[[#This Row],[3B]]*3)+(Cleaned_MLB_Stats_Dataset__1[[#This Row],[HR]]*4))/Cleaned_MLB_Stats_Dataset__1[[#This Row],[At Bats]] -> 0.49161074 | Z4: =Cleaned_MLB_Stats_Dataset__1[[#This Row],[On Base Percentage]]+Cleaned_MLB_Stats_Dataset__1[[#This Row],[Slugging %]] -> 0.81079083 | AA4: =Cleaned_MLB_Stats_Dataset__1[[#This Row],[Slugging %]]-Cleaned_MLB_Stats_Dataset__1[[#This Row],[Batting Average]] -> 0.26006711 | AB4: =Cleaned_MLB_Stats_Dataset__1[[#This Row],[Batting Average]]-_xlfn.XLOOKUP(Cleaned_MLB_Stats_Dataset__1[[#This Row],[Year]],'League Averages'!$A$3:$A$23,'League Averages'!$B$3:$B$23) -> -0.023456376 | AC4: =Cleaned_MLB_Stats_Dataset__1[[#This Row],[On Base Percentage]]-_xlfn.XLOOKUP(Cleaned_MLB_Stats_Dataset__1[[#This Row],[Year]],'League Averages'!$A$3:$A$23,'League Averages'!$C$3:$C$23) -> 0.00018008785 | AD4: =Cleaned_MLB_Stats_Dataset__1[[#This Row],[Slugging %]]-_xlfn.XLOOKUP(Cleaned_MLB_Stats_Dataset__1[[#This Row],[Year]],'League Averages'!$A$3:$A$23,'League Averages'!$D$3:$D$23) -> 0.086610738 | AE4: =Cleaned_MLB_Stats_Dataset__1[[#This Row],[OPS (On Base + Slugging)]]-_xlfn.XLOOKUP(Cleaned_MLB_Stats_Dataset__1[[#This Row],[Year]],'League Averages'!$A$3:$A$23,'League Averages'!$E$3:$E$23) -> 0.086790826 | AF4: =Cleaned_MLB_Stats_Dataset__1[[#This Row],[ISO (Isolated Power]]-_xlfn.XLOOKUP(Cleaned_MLB_Stats_Dataset__1[[#This Row],[Year]],'League Averages'!$A$3:$A$23,'League Averages'!$F$3:$F$23) -> 0.11006711
A5: Moneyball Era | B5: 2013 | C5: gonzaca01 | D5: NL | E5: COL | F5: =_xlfn.XLOOKUP(Cleaned_MLB_Stats_Dataset__1[[#This Row],[Position'#]],$B$373:$B$382,$A$373:$A$382) -> LF | G5: 7 | H5: 391 | I5: 118 | J5: 23 | K5: 6 | L5: 26 | M5: 72 | N5: 70 | O5: 118 | P5: 41 | Q5: 2 | R5: 1 | S5: 3 | T5: 0 | U5: =Cleaned_MLB_Stats_Dataset__1[[#This Row],[Hits]]/Cleaned_MLB_Stats_Dataset__1[[#This Row],[At Bats]] -> 0.30179028 | V5: =Cleaned_MLB_Stats_Dataset__1[[#This Row],[Strikeouts]]/(Cleaned_MLB_Stats_Dataset__1[[#This Row],[At Bats]]+Cleaned_MLB_Stats_Dataset__1[[#This Row],[Walks]]) -> 0.27314815 | W5: =(Cleaned_MLB_Stats_Dataset__1[[#This Row],[Walks]]+Cleaned_MLB_Stats_Dataset__1[[#This Row],[Hit By Pitch]])/(Cleaned_MLB_Stats_Dataset__1[[#This Row],[At Bats]]+Cleaned_MLB_Stats_Dataset__1[[#This Row],[Walks]]+Cleaned_MLB_Stats_Dataset__1[[#This Row],[Hit By Pitch]]) -> 0.096997691 | X5: =(Cleaned_MLB_Stats_Dataset__1[[#This Row],[Hits]]+Cleaned_MLB_Stats_Dataset__1[[#This Row],[Walks]]+Cleaned_MLB_Stats_Dataset__1[[#This Row],[Hit By Pitch]])/(Cleaned_MLB_Stats_Dataset__1[[#This Row],[At Bats]]+Cleaned_MLB_Stats_Dataset__1[[#This Row],[Walks]]+Cleaned_MLB_Stats_Dataset__1[[#This Row],[Hit By Pitch]]+Cleaned_MLB_Stats_Dataset__1[[#This Row],[Sac Fly]]) -> 0.36697248 | Y5: =((Cleaned_MLB_Stats_Dataset__1[[#This Row],[Hits]]-(Cleaned_MLB_Stats_Dataset__1[[#This Row],[2B]]+Cleaned_MLB_Stats_Dataset__1[[#This Row],[3B]]+Cleaned_MLB_Stats_Dataset__1[[#This Row],[HR]]))+(Cleaned_MLB_Stats_Dataset__1[[#This Row],[2B]]*2)+(Cleaned_MLB_Stats_Dataset__1[[#This Row],[3B]]*3)+(Cleaned_MLB_Stats_Dataset__1[[#This Row],[HR]]*4))/Cleaned_MLB_Stats_Dataset__1[[#This Row],[At Bats]] -> 0.59079284 | Z5: =Cleaned_MLB_Stats_Dataset__1[[#This Row],[On Base Percentage]]+Cleaned_MLB_Stats_Dataset__1[[#This Row],[Slugging %]] -> 0.95776532 | AA5: =Cleaned_MLB_Stats_Dataset__1[[#This Row],[Slugging %]]-Cleaned_MLB_Stats_Dataset__1[[#This Row],[Batting Average]] -> 0.28900256 | AB5: =Cleaned_MLB_Stats_Dataset__1[[#This Row],[Batting Average]]-_xlfn.XLOOKUP(Cleaned_MLB_Stats_Dataset__1[[#This Row],[Year]],'League Averages'!$A$3:$A$23,'League Averages'!$B$3:$B$23) -> 0.048790281 | AC5: =Cleaned_MLB_Stats_Dataset__1[[#This Row],[On Base Percentage]]-_xlfn.XLOOKUP(Cleaned_MLB_Stats_Dataset__1[[#This Row],[Year]],'League Averages'!$A$3:$A$23,'League Averages'!$C$3:$C$23) -> 0.048972477 | AD5: =Cleaned_MLB_Stats_Dataset__1[[#This Row],[Slugging %]]-_xlfn.XLOOKUP(Cleaned_MLB_Stats_Dataset__1[[#This Row],[Year]],'League Averages'!$A$3:$A$23,'League Averages'!$D$3:$D$23) -> 0.19479284 | AE5: =Cleaned_MLB_Stats_Dataset__1[[#This Row],[OPS (On Base + Slugging)]]-_xlfn.XLOOKUP(Cleaned_MLB_Stats_Dataset__1[[#This Row],[Year]],'League Averages'!$A$3:$A$23,'League Averages'!$E$3:$E$23) -> 0.24376532 | AF5: =Cleaned_MLB_Stats_Dataset__1[[#This Row],[ISO (Isolated Power]]-_xlfn.XLOOKUP(Cleaned_MLB_Stats_Dataset__1[[#This Row],[Year]],'League Averages'!$A$3:$A$23,'League Averages'!$F$3:$F$23) -> 0.14600256
A6: Moneyball Era | B6: 2012 | C6: ugglada01 | D6: NL | E6: ATL | F6: =_xlfn.XLOOKUP(Cleaned_MLB_Stats_Dataset__1[[#This Row],[Position'#]],$B$373:$B$382,$A$373:$A$382) -> 2B | G6: 4 | H6: 523 | I6: 115 | J6: 29 | K6: 0 | L6: 19 | M6: 86 | N6: 78 | O6: 168 | P6: 94 | Q6: 5 | R6: 10 | S6: 3 | T6: 0 | U6: =Cleaned_MLB_Stats_Dataset__1[[#This Row],[Hits]]/Cleaned_MLB_Stats_Dataset__1[[#This Row],[At Bats]] -> 0.21988528 | V6: =Cleaned_MLB_Stats_Dataset__1[[#This Row],[Strikeouts]]/(Cleaned_MLB_Stats_Dataset__1[[#This Row],[At Bats]]+Cleaned_MLB_Stats_Dataset__1[[#This Row],[Walks]]) -> 0.27228525 | W6: =(Cleaned_MLB_Stats_Dataset__1[[#This Row],[Walks]]+Cleaned_MLB_Stats_Dataset__1[[#This Row],[Hit By Pitch]])/(Cleaned_MLB_Stats_Dataset__1[[#This Row],[At Bats]]+Cleaned_MLB_Stats_Dataset__1[[#This Row],[Walks]]+Cleaned_MLB_Stats_Dataset__1[[#This Row],[Hit By Pitch]]) -> 0.16586922 | X6: =(Cleaned_MLB_Stats_Dataset__1[[#This Row],[Hits]]+Cleaned_MLB_Stats_Dataset__1[[#This Row],[Walks]]+Cleaned_MLB_Stats_Dataset__1[[#This Row],[Hit By Pitch]])/(Cleaned_MLB_Stats_Dataset__1[[#This Row],[At Bats]]+Cleaned_MLB_Stats_Dataset__1[[#This Row],[Walks]]+Cleaned_MLB_Stats_Dataset__1[[#This Row],[Hit By Pitch]]+Cleaned_MLB_Stats_Dataset__1[[#This Row],[Sac Fly]]) -> 0.34761905 | Y6: =((Cleaned_MLB_Stats_Dataset__1[[#This Row],[Hits]]-(Cleaned_MLB_Stats_Dataset__1[[#This Row],[2B]]+Cleaned_MLB_Stats_Dataset__1[[#This Row],[3B]]+Cleaned_MLB_Stats_Dataset__1[[#This Row],[HR]]))+(Cleaned_MLB_Stats_Dataset__1[[#This Row],[2B]]*2)+(Cleaned_MLB_Stats_Dataset__1[[#This Row],[3B]]*3)+(Cleaned_MLB_Stats_Dataset__1[[#This Row],[HR]]*4))/Cleaned_MLB_Stats_Dataset__1[[#This Row],[At Bats]] -> 0.38432122 | Z6: =Cleaned_MLB_Stats_Dataset__1[[#This Row],[On Base Percentage]]+Cleaned_MLB_Stats_Dataset__1[[#This Row],[Slugging %]] -> 0.73194027 | AA6: =Cleaned_MLB_Stats_Dataset__1[[#This Row],[Slugging %]]-Cleaned_MLB_Stats_Dataset__1[[#This Row],[Batting Average]] -> 0.16443595 | AB6: =Cleaned_MLB_Stats_Dataset__1[[#This Row],[Batting Average]]-_xlfn.XLOOKUP(Cleaned_MLB_Stats_Dataset__1[[#This Row],[Year]],'League Averages'!$A$3:$A$23,'League Averages'!$B$3:$B$23) -> -0.035114723 | AC6: =Cleaned_MLB_Stats_Dataset__1[[#This Row],[On Base Percentage]]-_xlfn.XLOOKUP(Cleaned_MLB_Stats_Dataset__1[[#This Row],[Year]],'League Averages'!$A$3:$A$23,'League Averages'!$C$3:$C$23) -> 0.028619048 | AD6: =Cleaned_MLB_Stats_Dataset__1[[#This Row],[Slugging %]]-_xlfn.XLOOKUP(Cleaned_MLB_Stats_Dataset__1[[#This Row],[Year]],'League Averages'!$A$3:$A$23,'League Averages'!$D$3:$D$23) -> -0.020678776 | AE6: =Cleaned_MLB_Stats_Dataset__1[[#This Row],[OPS (On Base + Slugging)]]-_xlfn.XLOOKUP(Cleaned_MLB_Stats_Dataset__1[[#This Row],[Year]],'League Averages'!$A$3:$A$23,'League Averages'!$E$3:$E$23) -> 0.0079402713 | AF6: =Cleaned_MLB_Stats_Dataset__1[[#This Row],[ISO (Isolated Power]]-_xlfn.XLOOKUP(Cleaned_MLB_Stats_Dataset__1[[#This Row],[Year]],'League Averages'!$A$3:$A$23,'League Averages'!$F$3:$F$23) -> 0.014435946
A7: Moneyball Era | B7: 2012 | C7: hamiljo03 | D7: AL | E7: TEX | F7: =_xlfn.XLOOKUP(Cleaned_MLB_Stats_Dataset__1[[#This Row],[Position'#]],$B$373:$B$382,$A$373:$A$382) -> LF | G7: 7 | H7: 562 | I7: 160 | J7: 31 | K7: 2 | L7: 43 | M7: 103 | N7: 128 | O7: 162 | P7: 60 | Q7: 13 | R7: 5 | S7: 9 | T7: 0 | U7: =Cleaned_MLB_Stats_Dataset__1[[#This Row],[Hits]]/Cleaned_MLB_Stats_Dataset__1[[#This Row],[At Bats]] -> 0.28469751 | V7: =Cleaned_MLB_Stats_Dataset__1[[#This Row],[Strikeouts]]/(Cleaned_MLB_Stats_Dataset__1[[#This Row],[At Bats]]+Cleaned_MLB_Stats_Dataset__1[[#This Row],[Walks]]) -> 0.26045016 | W7: =(Cleaned_MLB_Stats_Dataset__1[[#This Row],[Walks]]+Cleaned_MLB_Stats_Dataset__1[[#This Row],[Hit By Pitch]])/(Cleaned_MLB_Stats_Dataset__1[[#This Row],[At Bats]]+Cleaned_MLB_Stats_Dataset__1[[#This Row],[Walks]]+Cleaned_MLB_Stats_Dataset__1[[#This Row],[Hit By Pitch]]) -> 0.10366826 | X7: =(Cleaned_MLB_Stats_Dataset__1[[#This Row],[Hits]]+Cleaned_MLB_Stats_Dataset__1[[#This Row],[Walks]]+Cleaned_MLB_Stats_Dataset__1[[#This Row],[Hit By Pitch]])/(Cleaned_MLB_Stats_Dataset__1[[#This Row],[At Bats]]+Cleaned_MLB_Stats_Dataset__1[[#This Row],[Walks]]+Cleaned_MLB_Stats_Dataset__1[[#This Row],[Hit By Pitch]]+Cleaned_MLB_Stats_Dataset__1[[#This Row],[Sac Fly]]) -> 0.35377358 | Y7: =((Cleaned_MLB_Stats_Dataset__1[[#This Row],[Hits]]-(Cleaned_MLB_Stats_Dataset__1[[#This Row],[2B]]+Cleaned_MLB_Stats_Dataset__1[[#This Row],[3B]]+Cleaned_MLB_Stats_Dataset__1[[#This Row],[HR]]))+(Cleaned_MLB_Stats_Dataset__1[[#This Row],[2B]]*2)+(Cleaned_MLB_Stats_Dataset__1[[#This Row],[3B]]*3)+(Cleaned_MLB_Stats_Dataset__1[[#This Row],[HR]]*4))/Cleaned_MLB_Stats_Dataset__1[[#This Row],[At Bats]] -> 0.57651246 | Z7: =Cleaned_MLB_Stats_Dataset__1[[#This Row],[On Base Percentage]]+Cleaned_MLB_Stats_Dataset__1[[#This Row],[Slugging %]] -> 0.93028604 | AA7: =Cleaned_MLB_Stats_Dataset__1[[#This Row],[Slugging %]]-Cleaned_MLB_Stats_Dataset__1[[#This Row],[Batting Average]] -> 0.29181495 | AB7: =Cleaned_MLB_Stats_Dataset__1[[#This Row],[Batting Average]]-_xlfn.XLOOKUP(Cleaned_MLB_Stats_Dataset__1[[#This Row],[Year]],'League Averages'!$A$3:$A$23,'League Averages'!$B$3:$B$23) -> 0.029697509 | AC7: =Cleaned_MLB_Stats_Dataset__1[[#This Row],[On Base Percentage]]-_xlfn.XLOOKUP(Cleaned_MLB_Stats_Dataset__1[[#This Row],[Year]],'League Averages'!$A$3:$A$23,'League Averages'!$C$3:$C$23) -> 0.034773585 | AD7: =Cleaned_MLB_Stats_Dataset__1[[#This Row],[Slugging %]]-_xlfn.XLOOKUP(Cleaned_MLB_Stats_Dataset__1[[#This Row],[Year]],'League Averages'!$A$3:$A$23,'League Averages'!$D$3:$D$23) -> 0.17151246 | AE7: =Cleaned_MLB_Stats_Dataset__1[[#This Row],[OPS (On Base + Slugging)]]-_xlfn.XLOOKUP(Cleaned_MLB_Stats_Dataset__1[[#This Row],[Year]],'League Averages'!$A$3:$A$23,'League Averages'!$E$3:$E$23) -> 0.20628604 | AF7: =Cleaned_MLB_Stats_Dataset__1[[#This Row],[ISO (Isolated Power]]-_xlfn.XLOOKUP(Cleaned_MLB_Stats_Dataset__1[[#This Row],[Year]],'League Averages'!$A$3:$A$23,'League Averages'!$F$3:$F$23) -> 0.14181495
A8: Moneyball Era | B8: 2009 | C8: bayja01 | D8: AL | E8: BOS | F8: =_xlfn.XLOOKUP(Cleaned_MLB_Stats_Dataset__1[[#This Row],[Position'#]],$B$373:$B$382,$A$373:$A$382) -> LF | G8: 7 | H8: 531 | I8: 142 | J8: 29 | K8: 3 | L8: 36 | M8: 103 | N8: 119 | O8: 162 | P8: 94 | Q8: 4 | R8: 9 | S8: 4 | T8: 0 | U8: =Cleaned_MLB_Stats_Dataset__1[[#This Row],[Hits]]/Cleaned_MLB_Stats_Dataset__1[[#This Row],[At Bats]] -> 0.26741996 | V8: =Cleaned_MLB_Stats_Dataset__1[[#This Row],[Strikeouts]]/(Cleaned_MLB_Stats_Dataset__1[[#This Row],[At Bats]]+Cleaned_MLB_Stats_Dataset__1[[#This Row],[Walks]]) -> 0.2592 | W8: =(Cleaned_MLB_Stats_Dataset__1[[#This Row],[Walks]]+Cleaned_MLB_Stats_Dataset__1[[#This Row],[Hit By Pitch]])/(Cleaned_MLB_Stats_Dataset__1[[#This Row],[At Bats]]+Cleaned_MLB_Stats_Dataset__1[[#This Row],[Walks]]+Cleaned_MLB_Stats_Dataset__1[[#This Row],[Hit By Pitch]]) -> 0.16246057 | X8: =(Cleaned_MLB_Stats_Dataset__1[[#This Row],[Hits]]+Cleaned_MLB_Stats_Dataset__1[[#This Row],[Walks]]+Cleaned_MLB_Stats_Dataset__1[[#This Row],[Hit By Pitch]])/(Cleaned_MLB_Stats_Dataset__1[[#This Row],[At Bats]]+Cleaned_MLB_Stats_Dataset__1[[#This Row],[Walks]]+Cleaned_MLB_Stats_Dataset__1[[#This Row],[Hit By Pitch]]+Cleaned_MLB_Stats_Dataset__1[[#This Row],[Sac Fly]]) -> 0.38401254 | Y8: =((Cleaned_MLB_Stats_Dataset__1[[#This Row],[Hits]]-(Cleaned_MLB_Stats_Dataset__1[[#This Row],[2B]]+Cleaned_MLB_Stats_Dataset__1[[#This Row],[3B]]+Cleaned_MLB_Stats_Dataset__1[[#This Row],[HR]]))+(Cleaned_MLB_Stats_Dataset__1[[#This Row],[2B]]*2)+(Cleaned_MLB_Stats_Dataset__1[[#This Row],[3B]]*3)+(Cleaned_MLB_Stats_Dataset__1[[#This Row],[HR]]*4))/Cleaned_MLB_Stats_Dataset__1[[#This Row],[At Bats]] -> 0.53672316 | Z8: =Cleaned_MLB_Stats_Dataset__1[[#This Row],[On Base Percentage]]+Cleaned_MLB_Stats_Dataset__1[[#This Row],[Slugging %]] -> 0.9207357 | AA8: =Cleaned_MLB_Stats_Dataset__1[[#This Row],[Slugging %]]-Cleaned_MLB_Stats_Dataset__1[[#This Row],[Batting Average]] -> 0.2693032 | AB8: =Cleaned_MLB_Stats_Dataset__1[[#This Row],[Batting Average]]-_xlfn.XLOOKUP(Cleaned_MLB_Stats_Dataset__1[[#This Row],[Year]],'League Averages'!$A$3:$A$23,'League Averages'!$B$3:$B$23) -> 0.0054199623 | AC8: =Cleaned_MLB_Stats_Dataset__1[[#This Row],[On Base Percentage]]-_xlfn.XLOOKUP(Cleaned_MLB_Stats_Dataset__1[[#This Row],[Year]],'League Averages'!$A$3:$A$23,'League Averages'!$C$3:$C$23) -> 0.051012539 | AD8: =Cleaned_MLB_Stats_Dataset__1[[#This Row],[Slugging %]]-_xlfn.XLOOKUP(Cleaned_MLB_Stats_Dataset__1[[#This Row],[Year]],'League Averages'!$A$3:$A$23,'League Averages'!$D$3:$D$23) -> 0.11872316 | AE8: =Cleaned_MLB_Stats_Dataset__1[[#This Row],[OPS (On Base + Slugging)]]-_xlfn.XLOOKUP(Cleaned_MLB_Stats_Dataset__1[[#This Row],[Year]],'League Averages'!$A$3:$A$23,'League Averages'!$E$3:$E$23) -> 0.1697357 | AF8: =Cleaned_MLB_Stats_Dataset__1[[#This Row],[ISO (Isolated Power]]-_xlfn.XLOOKUP(Cleaned_MLB_Stats_Dataset__1[[#This Row],[Year]],'League Averages'!$A$3:$A$23,'League Averages'!$F$3:$F$23) -> 0.1133032
A9: Moneyball Era | B9: 2010 | C9: howarry01 | D9: NL | E9: PHI | F9: =_xlfn.XLOOKUP(Cleaned_MLB_Stats_Dataset__1[[#This Row],[Position'#]],$B$373:$B$382,$A$373:$A$382) -> DH | G9: 10 | H9: 550 | I9: 152 | J9: 23 | K9: 5 | L9: 31 | M9: 87 | N9: 108 | O9: 157 | P9: 59 | Q9: 11 | R9: 8 | S9: 3 | T9: 0 | U9: =Cleaned_MLB_Stats_Dataset__1[[#This Row],[Hits]]/Cleaned_MLB_Stats_Dataset__1[[#This Row],[At Bats]] -> 0.27636364 | V9: =Cleaned_MLB_Stats_Dataset__1[[#This Row],[Strikeouts]]/(Cleaned_MLB_Stats_Dataset__1[[#This Row],[At Bats]]+Cleaned_MLB_Stats_Dataset__1[[#This Row],[Walks]]) -> 0.25779967 | W9: =(Cleaned_MLB_Stats_Dataset__1[[#This Row],[Walks]]+Cleaned_MLB_Stats_Dataset__1[[#This Row],[Hit By Pitch]])/(Cleaned_MLB_Stats_Dataset__1[[#This Row],[At Bats]]+Cleaned_MLB_Stats_Dataset__1[[#This Row],[Walks]]+Cleaned_MLB_Stats_Dataset__1[[#This Row],[Hit By Pitch]]) -> 0.10858995 | X9: =(Cleaned_MLB_Stats_Dataset__1[[#This Row],[Hits]]+Cleaned_MLB_Stats_Dataset__1[[#This Row],[Walks]]+Cleaned_MLB_Stats_Dataset__1[[#This Row],[Hit By Pitch]])/(Cleaned_MLB_Stats_Dataset__1[[#This Row],[At Bats]]+Cleaned_MLB_Stats_Dataset__1[[#This Row],[Walks]]+Cleaned_MLB_Stats_Dataset__1[[#This Row],[Hit By Pitch]]+Cleaned_MLB_Stats_Dataset__1[[#This Row],[Sac Fly]]) -> 0.35322581 | Y9: =((Cleaned_MLB_Stats_Dataset__1[[#This Row],[Hits]]-(Cleaned_MLB_Stats_Dataset__1[[#This Row],[2B]]+Cleaned_MLB_Stats_Dataset__1[[#This Row],[3B]]+Cleaned_MLB_Stats_Dataset__1[[#This Row],[HR]]))+(Cleaned_MLB_Stats_Dataset__1[[#This Row],[2B]]*2)+(Cleaned_MLB_Stats_Dataset__1[[#This Row],[3B]]*3)+(Cleaned_MLB_Stats_Dataset__1[[#This Row],[HR]]*4))/Cleaned_MLB_Stats_Dataset__1[[#This Row],[At Bats]] -> 0.50545455 | Z9: =Cleaned_MLB_Stats_Dataset__1[[#This Row],[On Base Percentage]]+Cleaned_MLB_Stats_Dataset__1[[#This Row],[Slugging %]] -> 0.85868035 | AA9: =Cleaned_MLB_Stats_Dataset__1[[#This Row],[Slugging %]]-Cleaned_MLB_Stats_Dataset__1[[#This Row],[Batting Average]] -> 0.22909091 | AB9: =Cleaned_MLB_Stats_Dataset__1[[#This Row],[Batting Average]]-_xlfn.XLOOKUP(Cleaned_MLB_Stats_Dataset__1[[#This Row],[Year]],'League Averages'!$A$3:$A$23,'League Averages'!$B$3:$B$23) -> 0.019363636 | AC9: =Cleaned_MLB_Stats_Dataset__1[[#This Row],[On Base Percentage]]-_xlfn.XLOOKUP(Cleaned_MLB_Stats_Dataset__1[[#This Row],[Year]],'League Averages'!$A$3:$A$23,'League Averages'!$C$3:$C$23) -> 0.028225806 | AD9: =Cleaned_MLB_Stats_Dataset__1[[#This Row],[Slugging %]]-_xlfn.XLOOKUP(Cleaned_MLB_Stats_Dataset__1[[#This Row],[Year]],'League Averages'!$A$3:$A$23,'League Averages'!$D$3:$D$23) -> 0.10245455 | AE9: =Cleaned_MLB_Stats_Dataset__1[[#This Row],[OPS (On Base + Slugging)]]-_xlfn.XLOOKUP(Cleaned_MLB_Stats_Dataset__1[[#This Row],[Year]],'League Averages'!$A$3:$A$23,'League Averages'!$E$3:$E$23) -> 0.13068035 | AF9: =Cleaned_MLB_Stats_Dataset__1[[#This Row],[ISO (Isolated Power]]-_xlfn.XLOOKUP(Cleaned_MLB_Stats_Dataset__1[[#This Row],[Year]],'League Averages'!$A$3:$A$23,'League Averages'!$F$3:$F$23) -> 0.083090909
A10: Moneyball Era | B10: 2011 | C10: grandcu01 | D10: AL | E10: NYA | F10: =_xlfn.XLOOKUP(Cleaned_MLB_Stats_Dataset__1[[#This Row],[Position'#]],$B$373:$B$382,$A$373:$A$382) -> CF | G10: 8 | H10: 583 | I10: 153 | J10: 26 | K10: 10 | L10: 41 | M10: 136 | N10: 119 | O10: 169 | P10: 85 | Q10: 0 | R10: 12 | S10: 7 | T10: 4 | U10: =Cleaned_MLB_Stats_Dataset__1[[#This Row],[Hits]]/Cleaned_MLB_Stats_Dataset__1[[#This Row],[At Bats]] -> 0.26243568 | V10: =Cleaned_MLB_Stats_Dataset__1[[#This Row],[Strikeouts]]/(Cleaned_MLB_Stats_Dataset__1[[#This Row],[At Bats]]+Cleaned_MLB_Stats_Dataset__1[[#This Row],[Walks]]) -> 0.25299401 | W10: =(Cleaned_MLB_Stats_Dataset__1[[#This Row],[Walks]]+Cleaned_MLB_Stats_Dataset__1[[#This Row],[Hit By Pitch]])/(Cleaned_MLB_Stats_Dataset__1[[#This Row],[At Bats]]+Cleaned_MLB_Stats_Dataset__1[[#This Row],[Walks]]+Cleaned_MLB_Stats_Dataset__1[[#This Row],[Hit By Pitch]]) -> 0.14264706 | X10: =(Cleaned_MLB_Stats_Dataset__1[[#This Row],[Hits]]+Cleaned_MLB_Stats_Dataset__1[[#This Row],[Walks]]+Cleaned_MLB_Stats_Dataset__1[[#This Row],[Hit By Pitch]])/(Cleaned_MLB_Stats_Dataset__1[[#This Row],[At Bats]]+Cleaned_MLB_Stats_Dataset__1[[#This Row],[Walks]]+Cleaned_MLB_Stats_Dataset__1[[#This Row],[Hit By Pitch]]+Cleaned_MLB_Stats_Dataset__1[[#This Row],[Sac Fly]]) -> 0.36390102 | Y10: =((Cleaned_MLB_Stats_Dataset__1[[#This Row],[Hits]]-(Cleaned_MLB_Stats_Dataset__1[[#This Row],[2B]]+Cleaned_MLB_Stats_Dataset__1[[#This Row],[3B]]+Cleaned_MLB_Stats_Dataset__1[[#This Row],[HR]]))+(Cleaned_MLB_Stats_Dataset__1[[#This Row],[2B]]*2)+(Cleaned_MLB_Stats_Dataset__1[[#This Row],[3B]]*3)+(Cleaned_MLB_Stats_Dataset__1[[#This Row],[HR]]*4))/Cleaned_MLB_Stats_Dataset__1[[#This Row],[At Bats]] -> 0.55231561 | Z10: =Cleaned_MLB_Stats_Dataset__1[[#This Row],[On Base Percentage]]+Cleaned_MLB_Stats_Dataset__1[[#This Row],[Slugging %]] -> 0.91621663 | AA10: =Cleaned_MLB_Stats_Dataset__1[[#This Row],[Slugging %]]-Cleaned_MLB_Stats_Dataset__1[[#This Row],[Batting Average]] -> 0.28987993 | AB10: =Cleaned_MLB_Stats_Dataset__1[[#This Row],[Batting Average]]-_xlfn.XLOOKUP(Cleaned_MLB_Stats_Dataset__1[[#This Row],[Year]],'League Averages'!$A$3:$A$23,'League Averages'!$B$3:$B$23) -> 0.0074356775 | AC10: =Cleaned_MLB_Stats_Dataset__1[[#This Row],[On Base Percentage]]-_xlfn.XLOOKUP(Cleaned_MLB_Stats_Dataset__1[[#This Row],[Year]],'League Averages'!$A$3:$A$23,'League Averages'!$C$3:$C$23) -> 0.042901019 | AD10: =Cleaned_MLB_Stats_Dataset__1[[#This Row],[Slugging %]]-_xlfn.XLOOKUP(Cleaned_MLB_Stats_Dataset__1[[#This Row],[Year]],'League Averages'!$A$3:$A$23,'League Averages'!$D$3:$D$23) -> 0.15331561 | AE10: =Cleaned_MLB_Stats_Dataset__1[[#This Row],[OPS (On Base + Slugging)]]-_xlfn.XLOOKUP(Cleaned_MLB_Stats_Dataset__1[[#This Row],[Year]],'League Averages'!$A$3:$A$23,'League Averages'!$E$3:$E$23) -> 0.19621663 | AF10: =Cleaned_MLB_Stats_Dataset__1[[#This Row],[ISO (Isolated Power]]-_xlfn.XLOOKUP(Cleaned_MLB_Stats_Dataset__1[[#This Row],[Year]],'League Averages'!$A$3:$A$23,'League Averages'!$F$3:$F$23) -> 0.14587993
A11: Moneyball Era | B11: 2005 | C11: edmonji01 | D11: NL | E11: SLN | F11: =_xlfn.XLOOKUP(Cleaned_MLB_Stats_Dataset__1[[#This Row],[Position'#]],$B$373:$B$382,$A$373:$A$382) -> CF | G11: 8 | H11: 467 | I11: 123 | J11: 37 | K11: 1 | L11: 29 | M11: 88 | N11: 89 | O11: 139 | P11: 91 | Q11: 10 | R11: 4 | S11: 4 | T11: 1 | U11: =Cleaned_MLB_Stats_Dataset__1[[#This Row],[Hits]]/Cleaned_MLB_Stats_Dataset__1[[#This Row],[At Bats]] -> 0.2633833 | V11: =Cleaned_MLB_Stats_Dataset__1[[#This Row],[Strikeouts]]/(Cleaned_MLB_Stats_Dataset__1[[#This Row],[At Bats]]+Cleaned_MLB_Stats_Dataset__1[[#This Row],[Walks]]) -> 0.24910394 | W11: =(Cleaned_MLB_Stats_Dataset__1[[#This Row],[Walks]]+Cleaned_MLB_Stats_Dataset__1[[#This Row],[Hit By Pitch]])/(Cleaned_MLB_Stats_Dataset__1[[#This Row],[At Bats]]+Cleaned_MLB_Stats_Dataset__1[[#This Row],[Walks]]+Cleaned_MLB_Stats_Dataset__1[[#This Row],[Hit By Pitch]]) -> 0.16903915 | X11: =(Cleaned_MLB_Stats_Dataset__1[[#This Row],[Hits]]+Cleaned_MLB_Stats_Dataset__1[[#This Row],[Walks]]+Cleaned_MLB_Stats_Dataset__1[[#This Row],[Hit By Pitch]])/(Cleaned_MLB_Stats_Dataset__1[[#This Row],[At Bats]]+Cleaned_MLB_Stats_Dataset__1[[#This Row],[Walks]]+Cleaned_MLB_Stats_Dataset__1[[#This Row],[Hit By Pitch]]+Cleaned_MLB_Stats_Dataset__1[[#This Row],[Sac Fly]]) -> 0.38515901 | Y11: =((Cleaned_MLB_Stats_Dataset__1[[#This Row],[Hits]]-(Cleaned_MLB_Stats_Dataset__1[[#This Row],[2B]]+Cleaned_MLB_Stats_Dataset__1[[#This Row],[3B]]+Cleaned_MLB_Stats_Dataset__1[[#This Row],[HR]]))+(Cleaned_MLB_Stats_Dataset__1[[#This Row],[2B]]*2)+(Cleaned_MLB_Stats_Dataset__1[[#This Row],[3B]]*3)+(Cleaned_MLB_Stats_Dataset__1[[#This Row],[HR]]*4))/Cleaned_MLB_Stats_Dataset__1[[#This Row],[At Bats]] -> 0.53319058 | Z11: =Cleaned_MLB_Stats_Dataset__1[[#This Row],[On Base Percentage]]+Cleaned_MLB_Stats_Dataset__1[[#This Row],[Slugging %]] -> 0.91834959 | AA11: =Cleaned_MLB_Stats_Dataset__1[[#This Row],[Slugging %]]-Cleaned_MLB_Stats_Dataset__1[[#This Row],[Batting Average]] -> 0.26980728 | AB11: =Cleaned_MLB_Stats_Dataset__1[[#This Row],[Batting Average]]-_xlfn.XLOOKUP(Cleaned_MLB_Stats_Dataset__1[[#This Row],[Year]],'League Averages'!$A$3:$A$23,'League Averages'!$B$3:$B$23) -> -0.00061670236 | AC11: =Cleaned_MLB_Stats_Dataset__1[[#This Row],[On Base Percentage]]-_xlfn.XLOOKUP(Cleaned_MLB_Stats_Dataset__1[[#This Row],[Year]],'League Averages'!$A$3:$A$23,'League Averages'!$C$3:$C$23) -> 0.055159011 | AD11: =Cleaned_MLB_Stats_Dataset__1[[#This Row],[Slugging %]]-_xlfn.XLOOKUP(Cleaned_MLB_Stats_Dataset__1[[#This Row],[Year]],'League Averages'!$A$3:$A$23,'League Averages'!$D$3:$D$23) -> 0.11419058 | AE11: =Cleaned_MLB_Stats_Dataset__1[[#This Row],[OPS (On Base + Slugging)]]-_xlfn.XLOOKUP(Cleaned_MLB_Stats_Dataset__1[[#This Row],[Year]],'League Averages'!$A$3:$A$23,'League Averages'!$E$3:$E$23) -> 0.16934959 | AF11: =Cleaned_MLB_Stats_Dataset__1[[#This Row],[ISO (Isolated Power]]-_xlfn.XLOOKUP(Cleaned_MLB_Stats_Dataset__1[[#This Row],[Year]],'League Averages'!$A$3:$A$23,'League Averages'!$F$3:$F$23) -> 0.11480728
